Workbook
Name _Toc205793815: '0 - Summary'!#REF!
Name _Toc205793816: '0 - Summary'!#REF!
Name _Toc205793817: '0 - Summary'!#REF!

Sheet 0 - Summary
A1: ŞIRKƏT ADI : "İNDUSTRİAL SERVİCES CONSTRUCTİON GROUP" MMC
A2: İŞLƏRİN HƏCMİ VƏ QİYMƏT CƏDVƏLİ
A4: ÜMUMİ XÜLASƏ
A7: Ümumi xülasə | C7: Məbləğ
C8: AZN
A9: I. Ölçülmüş işlər Beton konstruksiya işləri (BOQ-Measured Works) | C9: ='1 - Direct_DK_BoQ'!L9 -> 997821.08
A10: II. Ölçülmüş işlər Memarlıq işləri (BOQ-Measured Works) | C10: ='2 - Direct_MH_BoQ'!L9 -> 178251.24
A11: III. İlkin və dolayı xərclər (Contractor's Preliminaries) | C11: ='3 - Indirect'!F40 -> 1609500
A12: IV. Üstəlik xərclər (Contractor's Overhead) | C12: ='4 - Overhead'!F20 -> 965400 | G12: =SUM(C11:C12)+I18 -> 2574900
A13: Şirkətin mənfəəti, % (Contractor's Gross Profit Margin, (%) | C13: =(C11+C12+C9+C10)*B13 -> 0 | G13: ='1 - Direct_DK_BoQ'!K6 -> 997821.08
A14: Yekun Muzd | B14: (A) | C14: =SUM(C9:C13) -> 3750972.3 | G14: =SUM(G12:G13) -> 3572721.1
A15: ƏDV (18 % x A) | B15: (B) | C15: =C14*0.18 -> 675175.02 | G15: =G14/G13 -> 3.5805228
A16: Yekun Muzd ƏDV ilə | B16: (C) | C16: =C14+C15 -> 4426147.3
G17: =C13 -> 0 | H17: ='1 - Direct_DK_BoQ'!J6 -> 0 | I17: ='1 - Direct_DK_BoQ'!K6 -> 997821.08 | J17: =SUM(H17:I17) -> 997821.08
H18: =$G$17*H17/$J$17 -> 0 | I18: =$G$17*I17/$J$17 -> 0
A19: Qeyd : Qeyd edilən bölmələri dəyərləndirən zaman "daxildir" praktikasından istifadə etmək olmaz, yəni bütün bəndlər balanslaşdırılmış şəkildə qiymətləndirilməlidir ! | H19: =SUM(H17:H18)/H17 -> #DIV/0!

Sheet 1 - Direct_DK_BoQ
B1: I HİSSƏ: ÖLÇÜLMÜŞ İŞLƏR / MEASURED WORKS
B2: Bənd | E2: Təsviri | F2: Vahid | G2: Miqdar | H2: Açıqlama | I2: Link vəya şəkil | J2: Müqavilə məbləği
J3: Vahid material qiyməti | K3: Vahid işçilik qiyməti | L3: Cəmi məbləğ
J4: AZN
B5: 1 | E5: Bu bölmədə əsas işlərin material və işçilik xərcləri orta bazar qiymətləri əsasında, balanslaşdırılmış şəkildə dəyərləndirilməlidir. Qiymətləndirmə zamanı material itkisi, sərfiyyat normaları və əmsallar, işlə bağlı tələb olunan köməkçi materiallar, materialların daşınması eləcə də gömrükləmə xərcləri nəzərə alınmalıdır. Bu işlərə dair üstəlik və dolayı xərclər, şirkətin mənfəəti vahid qiymətlərə daxil edilməməlidir və qiymət cədvəlinin I ci və II hissələrində öz əksini tapmalıdır. Burada qeyd edilmiş miqdarlar indikativ xarakter daşıyır. Həcmlərin hesablanmasında Sifarişçi tərəfindən təqdim edilən İşlərin Təsvirinə və Texniki Sənədlərə istinad edilməli və aşağıdakılarla məhdudlaşmayaraq İşlərə aid bütün detallar nəzərə alınmalıdır.
E6: Bakı şəhəri, Abşeron rayonu, Bilgəh qəsəbəsi, Zəfəran savxozu ərazisində yerləşən Fərdi yaşayış evi Əsas Bina və İtlər evində Memari işlər | J6: =SUMPRODUCT(J11:J67,$G$11:$G$67) -> 0 | K6: =SUMPRODUCT(K11:K67,$G$11:$G$67) -> 997821.08 | L6: =L7+#REF! -> #REF!
E7: Bakı şəhəri, Abşeron rayonu, Bilgəh qəsəbəsi, Zəfəran savxozu ərazisində yerləşən Fərdi yaşayış evi (Əsas Bina) Memarlıq və İnteryer işləri | L7: =L10+#REF!+#REF!+#REF!+#REF! -> #REF!
B8: 1 | E8: Bu bölmədə əsas işlərin material və işçilik xərcləri orta bazar qiymətləri əsasında, balanslaşdırılmış şəkildə dəyərləndirilməlidir. Qiymətləndirmə zamanı material itkisi, sərfiyyat normaları və əmsallar, işlə bağlı tələb olunan köməkçi materiallar, materialların daşınması eləcə də gömrükləmə xərcləri nəzərə alınmalıdır. Bu işlərə dair üstəlik və dolayı xərclər, şirkətin mənfəəti vahid qiymətlərə daxil edilməməlidir və qiymət cədvəlinin I ci və II hissələrində öz əksini tapmalıdır. Burada qeyd edilmiş miqdarlar indikativ xarakter daşıyır. Həcmlərin hesablanmasında Sifarişçi tərəfindən təqdim edilən İşlərin Təsvirinə və Texniki Sənədlərə istinad edilməli və aşağıdakılarla məhdudlaşmayaraq İşlərə aid bütün detallar nəzərə alınmalıdır.
E9: Ələt Azad İqtisadi Zonasında tikilməsi nəzərdə tutulan su anbarları, içməli və yağış suyu xətlərində Dəmir beton işləri | L9: =SUM(L10,L13,L16,L19,L25,L62) -> 997821.08
B10: 1 | C10: 1 | D10: 0 | E10: Qazıntı | L10: =SUM(L11:L12) -> 186615
B11: 1 | C11: 1 | D11: 1 | E11: Bünövrə oturma səviyyəsinə qədər səviyyələrin endirilməsi üçün qazıntı və qazıntı başa çatdıqdan sonra mexaniki üsulla sıxlaşdırma | F11: m3 | G11: 15455 | H11: (Yalnız işçilik qiymətləndiriləcəkdir) | K11: 8 | L11: =(J11+K11)*G11 -> 123640
B12: 1 | C12: 1 | D12: 2 | E12: Qazılmış torpağın utilizasiyası (daşınması) | F12: m3 | G12: 12595 | H12: (Yalnız işçilik qiymətləndiriləcəkdir) | K12: 5 | L12: =(J12+K12)*G12 -> 62975
B13: 1 | C13: 2 | D13: 0 | E13: Dolgu işləri | L13: =SUM(L14:L15) -> 7506
B14: 1 | C14: 2 | D14: 1 | E14: Spesifikasiyaya uyğun olaraq xırdalanmış çınqıl və ya qırmadaşdan istifadə etməklə doldurma və mexaniki üsulla sıxlaşdırma (h:100 mm) | F14: m3 | G14: 466 | H14: (Yalnız işçilik qiymətləndiriləcəkdir) | K14: 3.5 | L14: =(J14+K14)*G14 -> 1631
B15: 1 | C15: 2 | D15: 2 | E15: Əvvəlcədən qazılmış torpaqla geri doldurma | F15: m3 | G15: 2350 | H15: (Yalnız işçilik qiymətləndiriləcəkdir) | K15: 2.5 | L15: =(J15+K15)*G15 -> 5875
B16: 1 | C16: 3 | D16: 0 | E16: Qoruyucu qat | L16: =SUM(L17:L18) -> 11696
B17: 1 | C17: 3 | D17: 1 | E17: Beton altına polietilen salafan təbəqənin sərilməsi (Polietilen plyonka) | F17: m2 | G17: 4688 | H17: (Yalnız işçilik qiymətləndiriləcəkdir) | K17: 2 | L17: =(J17+K17)*G17 -> 9376
B18: 1 | C18: 3 | D18: 2 | E18: Hazırlıq qatı beton B7.5, bünövrə plitələri üçün hazırlıq qatı (h:100 mm) (Beton B7.5) | F18: m3 | G18: 464 | H18: (Yalnız işçilik qiymətləndiriləcəkdir) | K18: 5 | L18: =(J18+K18)*G18 -> 2320
B19: 1 | C19: 4 | D19: 0 | E19: İzolyasiya işləri | L19: =SUM(L20:L24) -> 81488.8
B20: 1 | C20: 4 | D20: 1 | E20: Bitumla yapışdırılmış 2qat ruberoidlə üfüqi hidroizolyasiya edilməsi | F20: m2 | G20: 4988 | H20: (Yalnız işçilik qiymətləndiriləcəkdir) | K20: 9 | L20: =(J20+K20)*G20 -> 44892
B21: 1 | C21: 4 | D21: 2 | E21: Qoruyucu-hamarlayıcı qatın sement məhlulundan düzəldilməsi 30mm | F21: m3 | G21: 229 | H21: (Yalnız işçilik qiymətləndiriləcəkdir) | K21: 7 | L21: =(J21+K21)*G21 -> 1603
B22: 1 | C22: 4 | D22: 3 | E22: Bitumla yapışdırılmış 2qat ruberoidlə üfüqi hidroizolyasiya edilməsi | F22: m2 | G22: 1066 | H22: (Yalnız işçilik qiymətləndiriləcəkdir) | K22: 9 | L22: =(J22+K22)*G22 -> 9594
B23: 1 | C23: 4 | D23: 4 | E23: XPS 50mm | F23: m2 | G23: 1411.1 | H23: (Yalnız işçilik qiymətləndiriləcəkdir) | K23: 4 | L23: =(J23+K23)*G23 -> 5644.4
B24: 1 | C24: 4 | D24: 5 | E24: Drenaj lövhəsinin (drain board) quraşdırılması | F24: m2 | G24: 1411.1 | H24: (Yalnız işçilik qiymətləndiriləcəkdir) | K24: 14 | L24: =(J24+K24)*G24 -> 19755.4
B25: 1 | C25: 5 | D25: 0 | E25: Dəmir beton işləri | L25: =SUM(L26,L32,L39,L45,L52,L57) -> 707452.27
B26: 1 | C26: 5 | D26: 1 | E26: Tava bünövrə | L26: =SUM(L27:L31) -> 219055.54
B27: 1 | C27: 5 | D27: 1 | E27: Sulfata davamlı beton B25 W8 | F27: m3 | G27: 1842.08 | H27: (Yalnız işçilik qiymətləndiriləcəkdir) | K27: 70 | L27: =(J27+K27)*G27 -> 128945.6
B28: 1 | C28: 5 | D28: 2 | E28: Qəlib işləri | F28: m2 | G28: 212 | H28: (Yalnız işçilik qiymətləndiriləcəkdir) | K28: 12 | L28: =(J28+K28)*G28 -> 2544
B29: 1 | C29: 5 | D29: 3 | E29: Armatur, sinif A500C Ø10 mm | F29: ton | G29: 0.192504 | H29: (Yalnız işçilik qiymətləndiriləcəkdir) | K29: 650 | L29: =(J29+K29)*G29 -> 125.1276
B30: 1 | C30: 5 | D30: 4 | E30: Armatur, sinif A500C Ø14 mm | F30: ton | G30: 125.9566 | H30: (Yalnız işçilik qiymətləndiriləcəkdir) | K30: 650 | L30: =(J30+K30)*G30 -> 81871.787
B31: 1 | C31: 5 | D31: 5 | E31: Armatur, sinif A-I (A240) Ø8 mm | F31: ton | G31: 8.5677372 | H31: (Yalnız işçilik qiymətləndiriləcəkdir) | K31: 650 | L31: =(J31+K31)*G31 -> 5569.0292
B32: 1 | C32: 6 | D32: 2 | E32: Sütunlar | L32: =SUM(L33:L38) -> 23547.615
B33: 1 | C33: =$C$32 -> 6 | D33: 1 | E33: Sulfata davamlı beton B25 W8 | F33: m3 | G33: 107.72 | H33: (Yalnız işçilik qiymətləndiriləcəkdir) | K33: 70 | L33: =(J33+K33)*G33 -> 7540.4
B34: 1 | C34: =$C$32 -> 6 | D34: 2 | E34: Qəlib işləri | F34: m2 | G34: 418.56 | H34: (Yalnız işçilik qiymətləndiriləcəkdir) | K34: 12 | L34: =(J34+K34)*G34 -> 5022.72
B35: 1 | C35: =$C$32 -> 6 | D35: 3 | E35: Armatur, sinif A500C Ø14 mm | F35: ton | G35: 3.4655104 | H35: (Yalnız işçilik qiymətləndiriləcəkdir) | K35: 650 | L35: =(J35+K35)*G35 -> 2252.5818
B36: 1 | C36: =$C$32 -> 6 | D36: 4 | E36: Armatur, sinif A500C Ø16 mm | F36: ton | G36: 7.188352 | H36: (Yalnız işçilik qiymətləndiriləcəkdir) | K36: 650 | L36: =(J36+K36)*G36 -> 4672.4288
B37: 1 | C37: =$C$32 -> 6 | D37: 5 | E37: Armatur, sinif A500C Ø18 mm | F37: ton | G37: 3.0002928 | H37: (Yalnız işçilik qiymətləndiriləcəkdir) | K37: 650 | L37: =(J37+K37)*G37 -> 1950.1903
B38: 1 | C38: =$C$32 -> 6 | D38: 6 | E38: Armatur, sinif A-I (A240) Ø8 mm | F38: ton | G38: 3.2450672 | H38: (Yalnız işçilik qiymətləndiriləcəkdir) | K38: 650 | L38: =(J38+K38)*G38 -> 2109.2937
B39: 1 | C39: 7 | D39: 3 | E39: Pərdə divarlar | L39: =SUM(L40:L44) -> 263602.79
B40: 1 | C40: =$C$39 -> 7 | D40: 1 | E40: Sulfata davamlı beton B25 W8 | F40: m3 | G40: 1035 | H40: (Yalnız işçilik qiymətləndiriləcəkdir) | K40: 70 | L40: =(J40+K40)*G40 -> 72450
...

Sheet Offer_Auto
B2: ='0 - Summary'!A1 -> ŞIRKƏT ADI : "İNDUSTRİAL SERVİCES CONSTRUCTİON GROUP" MMC
J3: =J9='0 - Summary'!C14 -> #DIV/0!
B4: III HİSSƏ: ÖLÇÜLMÜŞ İŞLƏR / MEASURED WORKS
B5: Bənd | E5: Təsviri | F5: Vahid | G5: Miqdar | H5: Müqavilə məbləği | K5: Müqavilə məbləği
H6: Vahid material qiyməti | I6: Vahid işçilik qiyməti | J6: Cəmi məbləğ | K6: Ümumi material qiyməti | L6: Ümumi işçilik qiyməti | M6: Cəmi məbləğ
H7: AZN | K7: AZN
B8: 1 | E8: Bu bölmədə əsas işlərin material və işçilik xərcləri orta bazar qiymətləri əsasında, balanslaşdırılmış şəkildə dəyərləndirilməlidir. Qiymətləndirmə zamanı material itkisi, sərfiyyat normaları və əmsallar, işlə bağlı tələb olunan köməkçi materiallar, materialların daşınması eləcə də gömrükləmə xərcləri nəzərə alınmalıdır. Bu işlərə dair üstəlik və dolayı xərclər, şirkətin mənfəəti vahid qiymətlərə daxil edilməməlidir və qiymət cədvəlinin I ci və II hissələrində öz əksini tapmalıdır. Burada qeyd edilmiş miqdarlar indikativ xarakter daşıyır. Həcmlərin hesablanmasında Sifarişçi tərəfindən təqdim edilən İşlərin Təsvirinə və Texniki Sənədlərə istinad edilməli və aşağıdakılarla məhdudlaşmayaraq İşlərə aid bütün detallar nəzərə alınmalıdır.
E9: Bakı şəhəri, Abşeron rayonu, Bilgəh qəsəbəsi, Zəfəran savxozu ərazisində yerləşən Fərdi yaşayış evi Əsas Bina və İtlər evində Memari işlər | J9: =J10+J183 -> #DIV/0! | M9: =M10+M183 -> #DIV/0!
E10: Bakı şəhəri, Abşeron rayonu, Bilgəh qəsəbəsi, Zəfəran savxozu ərazisində yerləşən Fərdi yaşayış evi (Əsas Bina) Memarlıq və İnteryer işləri | J10: =J11+J67+J134+J169+J174 -> #DIV/0! | M10: =M11+M67+M134+M169+M174 -> #DIV/0!
B11: 1 | C11: 0 | D11: 0 | E11: Divar işləri | J11: =J12+J17+J21+J26+J31+J36+J41+J45+J50+J55+J60+J65 -> #DIV/0! | K11: =K12+K17+K21+K26+K31+K36+K41+K45+K50+K55+K60+K65 -> #DIV/0! | L11: =L12+L17+L21+L26+L31+L36+L41+L45+L50+L55+L60+L65 -> #REF! | M11: =M12+M17+M21+M26+M31+M36+M41+M45+M50+M55+M60+M65 -> #DIV/0!
B12: 1 | C12: 1 | D12: 0 | E12: WF-1 Divar tipi | J12: =SUM(J13:J16) -> #DIV/0! | K12: =SUM(K13:K16) -> #DIV/0! | L12: =SUM(L13:L16) -> #REF! | M12: =SUM(M13:M16) -> #DIV/0!
B13: 1 | C13: 1 | D13: 1 | E13: WF-1 Boya, Betek, Max RAL 9010 | F13: m2 | G13: 1298 | H13: ='1 - Direct_DK_BoQ'!J11*'0 - Summary'!$H$19 -> #DIV/0! | I13: ='1 - Direct_DK_BoQ'!K11*'0 - Summary'!$G$15 -> 28.644182 | J13: =(H13+I13)*G13 -> #DIV/0! | K13: =H13*G13 -> #DIV/0! | L13: =I13*G13 -> 37180.148 | M13: =SUM(K13:L13) -> #DIV/0!
B14: 1 | C14: 1 | D14: 2 | E14: Binder | F14: m2 | G14: 1298 | H14: ='1 - Direct_DK_BoQ'!#REF!*'0 - Summary'!$H$19 -> #REF! | I14: ='1 - Direct_DK_BoQ'!#REF!*'0 - Summary'!$G$15 -> #REF! | J14: =(H14+I14)*G14 -> #REF! | K14: =H14*G14 -> #REF! | L14: =I14*G14 -> #REF! | M14: =SUM(K14:L14) -> #REF!
B15: 1 | C15: 1 | D15: 3 | E15: Üzlük 3mm (Cilalanma daxildir) | F15: m2 | G15: 1298 | H15: ='1 - Direct_DK_BoQ'!#REF!*'0 - Summary'!$H$19 -> #REF! | I15: ='1 - Direct_DK_BoQ'!#REF!*'0 - Summary'!$G$15 -> #REF! | J15: =(H15+I15)*G15 -> #REF! | K15: =H15*G15 -> #REF! | L15: =I15*G15 -> #REF! | M15: =SUM(K15:L15) -> #REF!
B16: 1 | C16: 1 | D16: 4 | E16: Fuqa gips (Aralıq doldurma qarışığı), (Dərziband qiymətə daxildir) | F16: m2 | G16: 1298 | H16: ='1 - Direct_DK_BoQ'!#REF!*'0 - Summary'!$H$19 -> #REF! | I16: ='1 - Direct_DK_BoQ'!#REF!*'0 - Summary'!$G$15 -> #REF! | J16: =(H16+I16)*G16 -> #REF! | K16: =H16*G16 -> #REF! | L16: =I16*G16 -> #REF! | M16: =SUM(K16:L16) -> #REF!
B17: 1 | C17: 2 | D17: 0 | E17: WF-2 Divar tipi | J17: =SUM(J18:J20) -> #DIV/0! | K17: =SUM(K18:K20) -> #DIV/0! | L17: =SUM(L18:L20) -> #REF! | M17: =SUM(M18:M20) -> #DIV/0!
B18: 1 | C18: 2 | D18: 1 | E18: WF-2 Ceramogranit, Albatros 101601, Beton texture, 60x120cm (Sadəcə işçilik üçün qiymət veiləcəkdir) | F18: m2 | G18: 49 | H18: ='1 - Direct_DK_BoQ'!J14*'0 - Summary'!$H$19 -> #DIV/0! | I18: ='1 - Direct_DK_BoQ'!K14*'0 - Summary'!$G$15 -> 12.53183 | J18: =(H18+I18)*G18 -> #DIV/0! | K18: =H18*G18 -> #DIV/0! | L18: =I18*G18 -> 614.05965 | M18: =SUM(K18:L18) -> #DIV/0!
B19: 1 | C19: 2 | D19: 2 | E19: Yapışdırıcı material 8m | F19: m2 | G19: 49 | H19: ='1 - Direct_DK_BoQ'!#REF!*'0 - Summary'!$H$19 -> #REF! | I19: ='1 - Direct_DK_BoQ'!#REF!*'0 - Summary'!$G$15 -> #REF! | J19: =(H19+I19)*G19 -> #REF! | K19: =H19*G19 -> #REF! | L19: =I19*G19 -> #REF! | M19: =SUM(K19:L19) -> #REF!
B20: 1 | C20: 2 | D20: 3 | E20: Sürmə Hidroizolyasiya qatı | F20: m2 | G20: 49 | H20: ='1 - Direct_DK_BoQ'!#REF!*'0 - Summary'!$H$19 -> #REF! | I20: ='1 - Direct_DK_BoQ'!#REF!*'0 - Summary'!$G$15 -> #REF! | J20: =(H20+I20)*G20 -> #REF! | K20: =H20*G20 -> #REF! | L20: =I20*G20 -> #REF! | M20: =SUM(K20:L20) -> #REF!
B21: 1 | C21: 3 | D21: 0 | E21: WF-3 Divar tipi | J21: =SUM(J22:J24) -> #DIV/0! | K21: =SUM(K22:K24) -> #DIV/0! | L21: =SUM(L22:L24) -> #REF! | M21: =SUM(M22:M24) -> #DIV/0!
B22: 1 | C22: 3 | D22: 1 | E22: WF-3 Plaster, Pitted PT L0006, Armourcoat | F22: m2 | G22: 1096 | H22: ='1 - Direct_DK_BoQ'!J17*'0 - Summary'!$H$19 -> #DIV/0! | I22: ='1 - Direct_DK_BoQ'!K17*'0 - Summary'!$G$15 -> 7.1610455 | J22: =(H22+I22)*G22 -> #DIV/0! | K22: =H22*G22 -> #DIV/0! | L22: =I22*G22 -> 7848.5059 | M22: =SUM(K22:L22) -> #DIV/0!
B23: 1 | C23: 3 | D23: 2 | E23: Binder | F23: m2 | G23: 1096 | H23: ='1 - Direct_DK_BoQ'!J18*'0 - Summary'!$H$19 -> #DIV/0! | I23: ='1 - Direct_DK_BoQ'!K18*'0 - Summary'!$G$15 -> 17.902614 | J23: =(H23+I23)*G23 -> #DIV/0! | K23: =H23*G23 -> #DIV/0! | L23: =I23*G23 -> 19621.265 | M23: =SUM(K23:L23) -> #DIV/0!
B24: 1 | C24: 3 | D24: 3 | E24: Üzlük 3mm (Cilalanma daxildir) | F24: m2 | G24: 1096 | H24: ='1 - Direct_DK_BoQ'!#REF!*'0 - Summary'!$H$19 -> #REF! | I24: ='1 - Direct_DK_BoQ'!#REF!*'0 - Summary'!$G$15 -> #REF! | J24: =(H24+I24)*G24 -> #REF! | K24: =H24*G24 -> #REF! | L24: =I24*G24 -> #REF! | M24: =SUM(K24:L24) -> #REF!
B25: 1 | C25: 3 | D25: 4 | E25: Fuqa gips (Aralıq doldurma qarışığı), (Dərziband qiymətə daxildir) | F25: m2 | G25: 1096 | H25: ='1 - Direct_DK_BoQ'!#REF!*'0 - Summary'!$H$19 -> #REF! | I25: ='1 - Direct_DK_BoQ'!#REF!*'0 - Summary'!$G$15 -> #REF! | J25: =(H25+I25)*G25 -> #REF! | K25: =H25*G25 -> #REF! | L25: =I25*G25 -> #REF! | M25: =SUM(K25:L25) -> #REF!
B26: 1 | C26: 4 | D26: 0 | E26: WF-4 Divar tipi | J26: =SUM(J27:J29) -> #DIV/0! | K26: =SUM(K27:K29) -> #DIV/0! | L26: =SUM(L27:L29) -> #REF! | M26: =SUM(M27:M29) -> #DIV/0!
B27: 1 | C27: 4 | D27: 1 | E27: WF-4 Boya, TIKV Tikkurila, WhiteTikkurila | F27: m2 | G27: 892 | H27: ='1 - Direct_DK_BoQ'!J20*'0 - Summary'!$H$19 -> #DIV/0! | I27: ='1 - Direct_DK_BoQ'!K20*'0 - Summary'!$G$15 -> 32.224705 | J27: =(H27+I27)*G27 -> #DIV/0! | K27: =H27*G27 -> #DIV/0! | L27: =I27*G27 -> 28744.437 | M27: =SUM(K27:L27) -> #DIV/0!
B28: 1 | C28: 4 | D28: 2 | E28: Binder | F28: m2 | G28: 892 | H28: ='1 - Direct_DK_BoQ'!J21*'0 - Summary'!$H$19 -> #DIV/0! | I28: ='1 - Direct_DK_BoQ'!K21*'0 - Summary'!$G$15 -> 25.063659 | J28: =(H28+I28)*G28 -> #DIV/0! | K28: =H28*G28 -> #DIV/0! | L28: =I28*G28 -> 22356.784 | M28: =SUM(K28:L28) -> #DIV/0!
B29: 1 | C29: 4 | D29: 3 | E29: Üzlük 3mm (Cilalanma daxildir) | F29: m2 | G29: 892 | H29: ='1 - Direct_DK_BoQ'!#REF!*'0 - Summary'!$H$19 -> #REF! | I29: ='1 - Direct_DK_BoQ'!#REF!*'0 - Summary'!$G$15 -> #REF! | J29: =(H29+I29)*G29 -> #REF! | K29: =H29*G29 -> #REF! | L29: =I29*G29 -> #REF! | M29: =SUM(K29:L29) -> #REF!
B30: 1 | C30: 4 | D30: 4 | E30: Fuqa gips (Aralıq doldurma qarışığı), (Dərziband qiymətə daxildir) | F30: m2 | G30: 892 | H30: ='1 - Direct_DK_BoQ'!#REF!*'0 - Summary'!$H$19 -> #REF! | I30: ='1 - Direct_DK_BoQ'!#REF!*'0 - Summary'!$G$15 -> #REF! | J30: =(H30+I30)*G30 -> #REF! | K30: =H30*G30 -> #REF! | L30: =I30*G30 -> #REF! | M30: =SUM(K30:L30) -> #REF!
B31: 1 | C31: 5 | D31: 0 | E31: WF-5 Divar tipi | J31: =SUM(J32:J34) -> #DIV/0! | K31: =SUM(K32:K34) -> #DIV/0! | L31: =SUM(L32:L34) -> #REF! | M31: =SUM(M32:M34) -> #DIV/0!
B32: 1 | C32: 5 | D32: 1 | E32: WF-5 Panel, , BespokeWood Wall Panel (Panelin quraşdırılması üçün alt materiallar qiymətə daxildir), (Sadəcə işçilik üçün qiymət veiləcəkdir) | F32: m2 | G32: 83 | H32: ='1 - Direct_DK_BoQ'!J26*'0 - Summary'!$H$19 -> #DIV/0! | I32: ='1 - Direct_DK_BoQ'!K26*'0 - Summary'!$G$15 -> 0 | J32: =(H32+I32)*G32 -> #DIV/0! | K32: =H32*G32 -> #DIV/0! | L32: =I32*G32 -> 0 | M32: =SUM(K32:L32) -> #DIV/0!
B33: 1 | C33: 5 | D33: 2 | E33: Binder | F33: m2 | G33: 83 | H33: ='1 - Direct_DK_BoQ'!#REF!*'0 - Summary'!$H$19 -> #REF! | I33: ='1 - Direct_DK_BoQ'!#REF!*'0 - Summary'!$G$15 -> #REF! | J33: =(H33+I33)*G33 -> #REF! | K33: =H33*G33 -> #REF! | L33: =I33*G33 -> #REF! | M33: =SUM(K33:L33) -> #REF!
B34: 1 | C34: 5 | D34: 3 | E34: Üzlük 3mm (Cilalanma daxildir) | F34: m2 | G34: 83 | H34: ='1 - Direct_DK_BoQ'!#REF!*'0 - Summary'!$H$19 -> #REF! | I34: ='1 - Direct_DK_BoQ'!#REF!*'0 - Summary'!$G$15 -> #REF! | J34: =(H34+I34)*G34 -> #REF! | K34: =H34*G34 -> #REF! | L34: =I34*G34 -> #REF! | M34: =SUM(K34:L34) -> #REF!
B35: 1 | C35: 5 | D35: 4 | E35: Fuqa gips (Aralıq doldurma qarışığı), (Dərziband qiymətə daxildir) | F35: m2 | G35: 83 | H35: ='1 - Direct_DK_BoQ'!#REF!*'0 - Summary'!$H$19 -> #REF! | I35: ='1 - Direct_DK_BoQ'!#REF!*'0 - Summary'!$G$15 -> #REF! | J35: =(H35+I35)*G35 -> #REF! | K35: =H35*G35 -> #REF! | L35: =I35*G35 -> #REF! | M35: =SUM(K35:L35) -> #REF!
B36: 1 | C36: 6 | D36: 0 | E36: WF-6 Divar tipi | J36: =SUM(J37:J39) -> #DIV/0! | K36: =SUM(K37:K39) -> #DIV/0! | L36: =SUM(L37:L39) -> #REF! | M36: =SUM(M37:M39) -> #DIV/0!
B37: 1 | C37: 6 | D37: 1 | E37: WF-6 Panel, Bespoke, Wood Wall Panel (Panelin quraşdırılması üçün alt materiallar qiymətə daxildir) (Sadəcə işçilik üçün qiymət veiləcəkdir) | F37: m2 | G37: 43 | H37: ='1 - Direct_DK_BoQ'!J63*'0 - Summary'!$H$19 -> #DIV/0! | I37: ='1 - Direct_DK_BoQ'!K63*'0 - Summary'!$G$15 -> 3222.4705 | J37: =(H37+I37)*G37 -> #DIV/0! | K37: =H37*G37 -> #DIV/0! | L37: =I37*G37 -> 138566.23 | M37: =SUM(K37:L37) -> #DIV/0!
B38: 1 | C38: 6 | D38: 2 | E38: Binder | F38: m2 | G38: 43 | H38: ='1 - Direct_DK_BoQ'!J64*'0 - Summary'!$H$19 -> #DIV/0! | I38: ='1 - Direct_DK_BoQ'!K64*'0 - Summary'!$G$15 -> 3222.4705 | J38: =(H38+I38)*G38 -> #DIV/0! | K38: =H38*G38 -> #DIV/0! | L38: =I38*G38 -> 138566.23 | M38: =SUM(K38:L38) -> #DIV/0!
B39: 1 | C39: 6 | D39: 3 | E39: Üzlük 3mm (Cilalanma daxildir) | F39: m2 | G39: 43 | H39: ='1 - Direct_DK_BoQ'!#REF!*'0 - Summary'!$H$19 -> #REF! | I39: ='1 - Direct_DK_BoQ'!#REF!*'0 - Summary'!$G$15 -> #REF! | J39: =(H39+I39)*G39 -> #REF! | K39: =H39*G39 -> #REF! | L39: =I39*G39 -> #REF! | M39: =SUM(K39:L39) -> #REF!
B40: 1 | C40: 6 | D40: 4 | E40: Fuqa gips (Aralıq doldurma qarışığı), (Dərziband qiymətə daxildir) | F40: m2 | G40: 43 | H40: ='1 - Direct_DK_BoQ'!#REF!*'0 - Summary'!$H$19 -> #REF! | I40: ='1 - Direct_DK_BoQ'!#REF!*'0 - Summary'!$G$15 -> #REF! | J40: =(H40+I40)*G40 -> #REF! | K40: =H40*G40 -> #REF! | L40: =I40*G40 -> #REF! | M40: =SUM(K40:L40) -> #REF!
B41: 1 | C41: 7 | D41: 0 | E41: WF-19 Divar tipi | J41: =SUM(J42:J44) -> #REF! | K41: =SUM(K42:K44) -> #REF! | L41: =SUM(L42:L44) -> #REF! | M41: =SUM(M42:M44) -> #REF!
...

Sheet 2 - Direct_MH_BoQ
B1: I HİSSƏ: ÖLÇÜLMÜŞ İŞLƏR / MEASURED WORKS
B2: Bənd | E2: Təsviri | F2: Vahid | G2: Miqdar | H2: Açıqlama | I2: Link vəya şəkil | J2: Müqavilə məbləği
J3: Vahid material qiyməti | K3: Vahid işçilik qiyməti | L3: Cəmi məbləğ
J4: AZN
B5: 1 | E5: Bu bölmədə əsas işlərin material və işçilik xərcləri orta bazar qiymətləri əsasında, balanslaşdırılmış şəkildə dəyərləndirilməlidir. Qiymətləndirmə zamanı material itkisi, sərfiyyat normaları və əmsallar, işlə bağlı tələb olunan köməkçi materiallar, materialların daşınması eləcə də gömrükləmə xərcləri nəzərə alınmalıdır. Bu işlərə dair üstəlik və dolayı xərclər, şirkətin mənfəəti vahid qiymətlərə daxil edilməməlidir və qiymət cədvəlinin I ci və II hissələrində öz əksini tapmalıdır. Burada qeyd edilmiş miqdarlar indikativ xarakter daşıyır. Həcmlərin hesablanmasında Sifarişçi tərəfindən təqdim edilən İşlərin Təsvirinə və Texniki Sənədlərə istinad edilməli və aşağıdakılarla məhdudlaşmayaraq İşlərə aid bütün detallar nəzərə alınmalıdır.
E6: Bakı şəhəri, Abşeron rayonu, Bilgəh qəsəbəsi, Zəfəran savxozu ərazisində yerləşən Fərdi yaşayış evi Əsas Bina və İtlər evində Memari işlər | J6: =SUMPRODUCT(J11:J28,$G$11:$G$28) -> 0 | K6: =SUMPRODUCT(K11:K28,$G$11:$G$28) -> 152508.24 | L6: =L7+#REF! -> #REF!
E7: Bakı şəhəri, Abşeron rayonu, Bilgəh qəsəbəsi, Zəfəran savxozu ərazisində yerləşən Fərdi yaşayış evi (Əsas Bina) Memarlıq və İnteryer işləri | L7: =#REF!+#REF!+#REF!+#REF!+#REF! -> #REF!
B8: 1 | E8: Bu bölmədə əsas işlərin material və işçilik xərcləri orta bazar qiymətləri əsasında, balanslaşdırılmış şəkildə dəyərləndirilməlidir. Qiymətləndirmə zamanı material itkisi, sərfiyyat normaları və əmsallar, işlə bağlı tələb olunan köməkçi materiallar, materialların daşınması eləcə də gömrükləmə xərcləri nəzərə alınmalıdır. Bu işlərə dair üstəlik və dolayı xərclər, şirkətin mənfəəti vahid qiymətlərə daxil edilməməlidir və qiymət cədvəlinin I ci və II hissələrində öz əksini tapmalıdır. Burada qeyd edilmiş miqdarlar indikativ xarakter daşıyır. Həcmlərin hesablanmasında Sifarişçi tərəfindən təqdim edilən İşlərin Təsvirinə və Texniki Sənədlərə istinad edilməli və aşağıdakılarla məhdudlaşmayaraq İşlərə aid bütün detallar nəzərə alınmalıdır.
E9: Ələt Azad İqtisadi Zonasında tikilməsi nəzərdə tutulan su anbarları, içməli və yağış suyu xətlərinin tikintisi Memarlıq işləri | L9: =SUM(L10,L14,L16,L19,L21,L24,L27) -> 178251.24
B10: 1 | C10: 1 | D10: 0 | E10: Keramik | L10: =SUM(L12:L14) -> 34003.6
B11: 1 | C11: 1 | D11: 1 | E11: Keramik plitələr | F11: m2 | G11: 210.6 | H11: (Yalnız işçilik qiymətləndiriləcəkdir) | K11: 25 | L11: =(J11+K11)*G11 -> 5265
B12: 1 | C12: 1 | D12: 2 | E12: Sement məhlulu ilə stəjka, qalınlığı 30 mm | F12: m2 | G12: 210.6 | H12: (Yalnız işçilik qiymətləndiriləcəkdir) | K12: 10 | L12: =(J12+K12)*G12 -> 2106
B13: 1 | C13: 1 | D13: 3 | E13: Keramik plintus (h=100 mm) | F13: m | G13: 111.2 | H13: (Yalnız işçilik qiymətləndiriləcəkdir) | K13: 8 | L13: =(J13+K13)*G13 -> 889.6
B14: 1 | C14: 2 | D14: 0 | E14: Epoksid | L14: =SUM(L15:L15) -> 31008
B15: 1 | C15: 2 | D15: 1 | E15: Su keçirməyən örtük (brend alternativləri və ya oxşar məhsullar: Sika Top Seal 107, BASF Ancronal 5442) | F15: m2 | G15: 3876 | H15: (Yalnız işçilik qiymətləndiriləcəkdir) | K15: 8 | L15: =(J15+K15)*G15 -> 31008
B16: 1 | C16: 3 | D16: 0 | E16: Qranit | L16: =SUM(L17:L18) -> 1341.8
B17: 1 | C17: 3 | D17: 1 | E17: Qumla fırçalanmış qranit üzlük, 600x400x20 m | F17: m2 | G17: 37 | H17: (Yalnız işçilik qiymətləndiriləcəkdir) | K17: 25 | L17: =(J17+K17)*G17 -> 925
B18: 1 | C18: 3 | D18: 2 | E18: Qranit plintus (h=100 mm) | F18: m | G18: 52.1 | H18: (Yalnız işçilik qiymətləndiriləcəkdir) | K18: 8 | L18: =(J18+K18)*G18 -> 416.8
B19: 1 | C19: 4 | D19: 0 | E19: Pilləkan qranit | L19: =SUM(L20:L20) -> 825
B20: 1 | C20: 4 | D20: 1 | E20: Giriş pilləkənləri, Qranit pillə üzlüyü (basamaq 30 mm, qaldırıcı 20 mm) | F20: ədəd | G20: 33 | H20: (Yalnız işçilik qiymətləndiriləcəkdir) | K20: 25 | L20: =(J20+K20)*G20 -> 825
B21: 1 | C21: 5 | D21: 0 | E21: TAVAN | L21: =SUM(L22:L23) -> 69629.84
B22: 1 | C22: 5 | D22: 1 | E22: Su keçirməyən örtük (brend alternativləri və ya oxşar məhsullar: Sika Top Seal 107, BASF Ancronal 5442), Sement-polimer hidroizolyasiya (Sika Top Seal 107 və ya ekv.) | F22: m2 | G22: 4508.4 | H22: (Yalnız işçilik qiymətləndiriləcəkdir) | K22: 15 | L22: =(J22+K22)*G22 -> 67626
B23: 1 | C23: =$C$21 -> 5 | D23: 2 | E23: Suya davamlı emulsiya boyası (rütubət üçün, RAL-9010, brend alternativləri və ya oxşar məhsullar: JOTUN, BETEK), | F23: m2 | G23: 250.48 | H23: (Yalnız işçilik qiymətləndiriləcəkdir) | K23: 8 | L23: =(J23+K23)*G23 -> 2003.84
B24: 1 | C24: 6 | D24: 0 | E24: DİVAR | L24: =SUM(L25:L26) -> 41223
B25: 1 | C25: =$C$24 -> 6 | D25: 1 | E25: Sement-polimer əsaslı iki komponentli su keçirməyən qoruyucu örtük (brend alternativləri və ya oxşar məhsullar: Sika Top Seal 107, BASF Ancronal 5442) | F25: m2 | G25: 2521 | H25: (Yalnız işçilik qiymətləndiriləcəkdir) | K25: 15 | L25: =(J25+K25)*G25 -> 37815
B26: 1 | C26: =$C$24 -> 6 | D26: =D25+1 -> 2 | E26: Suya davamlı emulsiya boyası (rütubət üçün, RAL-9010, brend alternativləri və ya oxşar məhsullar: JOTUN, BETEK) | F26: m2 | G26: 426 | H26: (Yalnız işçilik qiymətləndiriləcəkdir) | K26: 8 | L26: =(J26+K26)*G26 -> 3408
B27: 1 | C27: 7 | D27: 0 | E27: Qapılar | L27: =SUM(L28:L28) -> 220
B28: 1 | C28: =$C$27 -> 7 | D28: 1 | E28: Xarici yanğına davamlı qapı (boyalı RAL-7036, brend alternativləri və ya oxşar məhsullar: MKSmetal), Yanğına davamlı metal qapı EI120, 3200x3100 mm | F28: ədəd | G28: 2 | H28: (Yalnız işçilik qiymətləndiriləcəkdir) | K28: 110 | L28: =(J28+K28)*G28 -> 220

Sheet 3 - Indirect
A1: II HİSSƏ: İLKİN VƏ DOLAYI XƏRCLƏR / PRELİMİNARİES
A2: Bənd | B2: Təsviri | C2: Vahid | D2: Miqdar | E2: Müqavilə məbləği
E3: Vahid qiyməti | F3: Məbləğ
E4: AZN
A5: 2 | B5: Bu bölməyə layihə ilə bağlı üstəlik xərclər, o cümlədən administrativ xərclər, vergi və rüsum ödənişləri, əməyin təhlükəsizliyi ilə bağlı xərclər, baş ofisin xərcləri daxildir
A6: 2.1 | B6: Bütün ixtisaslı işçi heyətinin əmək haqları, Vizalar, İş icazələri, İşçilərə ödənilən kompensasiyalar, bonuslar və əmək məzuniyyəti (həmçinin xarici vətəndaşdırsa) və bunla bağlı olan səyahət xərcləri də daxil olan və bununla məhdudlaşmayan digər xərclər daxildir.
A7: 2.1.1 | B7: ___________ işləri üzrə Layihə Meneceri | C7: cəm | D7: 1 | E7: 48000 | F7: =D7*E7 -> 48000
A8: 2.1.2 | B8: ___________ işləri üzrə Menecer köməkçisi | C8: cəm | D8: 2 | E8: 30000 | F8: =D8*E8 -> 60000
A9: 2.1.3 | B9: Planlama üzrə Menecer | C9: cəm | D9: 1 | E9: 21600 | F9: =D9*E9 -> 21600
A10: 2.1.4 | B10: Layihələndirmə üzrə Menecer | C10: cəm | D10: 1 | E10: 42000 | F10: =D10*E10 -> 42000
A11: 2.1.5 | B11: İşçi layihələrin (Shopdrawings, As-built) hazırlanması üçün sahədə texniki komanda (İcraçı işlərin, təqdim edəcək bütün layihələndirmə məlumatlarının faktiki sahə ölçülərinə (as-built) uyğunlaşdırılmış olaraq dizayn etməli və faktiki ölçülər ilə fərqliliyə yol verməməlidir. Faktiki ölçülərdəki digər İcraçılara aid sapma və kənarlaşmalar norma və standartlar daxilində nəzərə alınmalıdır) | C11: cəm | D11: 4 | E11: 30000 | F11: =D11*E11 -> 120000
A12: 2.1.6 | B12: İşçi layihələrin (Shopdrawings) hazırlanması üçün sahə xaricində texniki komanda | C12: cəm | D12: 2 | E12: 2500 | F12: =D12*E12 -> 5000
A13: 2.1.7 | B13: Tikinti üzrə Menecer - ___________ işləri | C13: cəm | D13: 1 | E13: 1800 | F13: =D13*E13 -> 1800
A14: 2.1.8 | B14: Tikinti üzrə Menecer - ___________ işləri | C14: cəm | D14: 1 | E14: 1800 | F14: =D14*E14 -> 1800
A15: 2.1.9 | B15: Müvafiq sayda Nəzarətçi heyət (say qeyd edilməlidir) | C15: cəm | D15: 2 | E15: 2200 | F15: =D15*E15 -> 4400
A16: 2.1.10 | B16: Sınaq və İstismara vermə işləri – Mühəndis | C16: cəm | D16: 1 | E16: 2500 | F16: =D16*E16 -> 2500
A17: 2.1.11 | B17: Sınaq və İstismara vermə işləri – Mühəndis köməkçiləri | C17: cəm | D17: 1 | E17: 2500 | F17: =D17*E17 -> 2500
A18: 2.1.12 | B18: QA/QC - Menecer | C18: cəm | D18: 1 | E18: 36000 | F18: =D18*E18 -> 36000
... A25: 2.1.19 | B25: Digər nəzərdə tutulan işçilər | C25: cəm | D25: 1 | E25: 18000 | F25: =D25*E25 -> 18000
A26: 2.2 | B26: İşçi heyətinin yaşayış və məskunlaşma xərcləri | C26: cəm | D26: 50 | E26: 2880 | F26: =D26*E26 -> 144000
A27: 2.3 | B27: İşçi heyətinin bütün təhlükəsizlik, sağlamlıq və yaşayış qaydalarına riayət etməsi üçün bütün xərclər və haqlar. | C27: cəm | D27: 50 | E27: 540 | F27: =D27*E27 -> 27000
A28: 2.4 | B28: İşçi heyətinin fərdi mühafizə vasitələri ilə təmin edilməsi ilə bağlı bütün xərclər | C28: cəm | D28: 50 | E28: 250 | F28: =D28*E28 -> 12500
A29: 2.5 | B29: İşçi heyətinin sahəyə və oradan daşınması xərcləri | C29: cəm | D29: 50 | E29: 1800 | F29: =D29*E29 -> 90000
A30: 2.6 | B30: İşçi heyətinin yemək xərcləri | C30: cəm | D30: 50 | E30: 5400 | F30: =D30*E30 -> 270000
A31: 2.7 | B31: İşçi heyətinin mobilizasiyası | C31: cəm | D31: 50 | E31: 450 | F31: =D31*E31 -> 22500
A32: 2.8 | B32: İşçi heyətinin demobilizsiyası | C32: cəm | D32: 50 | E32: 450 | F32: =D32*E32 -> 22500
A33: 2.9 | B33: İcraçının sağlamlıq və əməyin təhlükəsizliyi və ətraf mühitin mühafizəsi və bununla bağlı zəruri tədbirlərin görülməsinə çəkilən xərclər | C33: cəm | D33: 50 | E33: 720 | F33: =D33*E33 -> 36000
A34: 2.1 | B34: Sahə təhlükəsizlik sistemlərinin təmin olunması | C34: cəm | D34: 50 | E34: 720 | F34: =D34*E34 -> 36000
A35: 2.11 | B35: Qanunvericiliklə nəzərdə tutulmuş bütün Vergilər, Rüsumlar, Bank xərcləri, bütün işçi heyətinin səhiyyə və pensiya ödənişi, sosial təminat haqları və s. | C35: cəm | D35: 50 | E35: 7128 | F35: =D35*E35 -> 356400
A36: 2.12 | B36: İcraçının özünə aid olan enerji təchizatı və işıq haqları, su təchizatı, içməli su və sərf materialları da daxil olmaqla ofis, düşərgə, ayaqyolu və digər müvəqqəti qurğuların istismarı və onlara texniki xidmət xərcləri | C36: cəm | D36: 10 | E36: 1800 | F36: =D36*E36 -> 18000
A37: 2.13 | B37: İcraçının özünü bütün mobil telefonlarla təmin etməsi və bütün xidmət haqları və aylıq hesabları öz hesabına ödəməsi | C37: cəm | D37: 10 | E37: 240 | F37: =D37*E37 -> 2400
A38: 2.14 | B38: Tikinti işlərinin planı, proqramı (qrafiki), işçi cizgilər, tikintidən əvvəlki vəziyyəti və işin gedişatını əks etdirən fotolar, faktiki icra cizgiləri, işin gedişatı, keyfiyyətə nəzarət, təhlükəsizliyə nəzarət, ətraf mühitə nəzarət üzrə hesabatların və digər sənədlərin hazırlanması və təqdim edilməsi | C38: cəm | F38: 90000
A39: 2.16 | B39: İcraçının bütün tələb edilən nümunələr, təcrübi modellər, prototiplər, sınaq və yoxlanışlar, əlaqədar sınaq verilənləri və sertifikatlarla Sifarişçiyə təqdim edilməsi | C39: cəm | F39: 50000
A40: CƏM: | F40: =SUM(F5:F39) -> 1609500

Sheet 4 - Overhead
A1: III HİSSƏ: ÜSTƏLİK XƏRCLƏR / OVERHEAD
A2: Bənd | B2: Təsviri | C2: Vahid | D2: Miqdar | E2: Müqavilə məbləği
E3: Vahid qiyməti | F3: Məbləğ
E4: AZN
A5: 1 | B5: Bu bölməyə layihə ilə bağlı ilkin və dolayı xərclər və eləcə də mobilizasiya və demobilizasiya işləri və onların dəyərləndirilməsi daxildir.
A6: 1.1 | B6: Zəmanət və Sığorta
A7: 1.1.1 | B7: İcra zəmanətinin təmin edilməsi 5% | C7: cəm | F7: =D7*E7 -> 0
A8: 1.1.2 | B8: Avans zəmanətinin təmin edilməsi | C8: cəm | F8: =D8*E8 -> 0
A9: 1.1.3 | B9: İşəgötürənin məsuliyyət sığortası, maşın mexanizm, texnika və avadanlıqların icbari sığortası, üçüncü şəxsələr qarşısında məsuliyyət sığortası | C9: cəm | F9: 12000
A10: 1.2 | B10: Mobilizasiya xərcləri | F10: =D10*E10 -> 0
A11: 1.2.1 | B11: Layihənin icrası üçün lazım olan Sahə ofisi və texniki işçilərin işə cəlb edilməsi xərcləri, ofis və ambar konteynerləri, kompyuter, printer, skaner, plotter vasitələri və işin icrası üçün tələb olunan software proqramları, mebel, dəftərxana, avadanlıqları, internet, telefon və s. xərclər, avtonəqliyat vasitələri, yoxlama, nəzarət, hazırlıq işləri üçün alət və avadanlıqlar (məsələn test avadanlığı, total station, nivelir və s.) məişət avadanlıqları və kondisionerlər, köməkçi vasitələr və s. daxildir. | C11: cəm | F11: 45000
A12: 1.2.2 | B12: Müvəqqəti meydança (ərazi), hasar, barrikada, siqnal lampası, işıqlandırma, xəbərdarlıq işarələri, plakatlar, müvəqqəti tutacaqlar, baryerlər, kənar müdafiə, lövhələr və hər növ təhlükəsizlik ilə əlaqədar önləyici tədbirlərin nəzərə alınması xərcləri | C12: cəm | F12: 38000
A13: 1.3 | B13: Avadanlıqların, Qurğuların, Maşın və Mexanizmlərin və s. təmin olunması | F13: =D13*E13 -> 0
A14: 1.5.1 | B14: İşlərin yerinə yetirilməsi üçün lazım olan bütün qurğuların, avadanlıqların, maşın və texnikaların, əl alətlərinin təmin edilməsi xərcləri | C14: cəm | F14: 722000
A15: 1.3.2 | B15: Taxtabəndlərin (ayaqaltıların) quraşdırılması və çıxarılması daxil olmaqla İşlərin vaxtında həyata keçirilməsi və tamamlanması üçün zəruri olan bütün müvəqqəti taxtabənd və aksessuarlarla təmin edilməsi xərcləri. | C15: cəm | D15: 60 | E15: 390 | F15: =D15*E15 -> 23400
A16: 1.5.3 | B16: Şaquli və üfüqi daşımalar (müvəqqəti lift, servis yükləmə platforması və s.), qaldırıcı meydançalar, asma meydançaları, nəqliyyat vasitələri, vasitələr və xidmətlər daxil olmaqla bütün inşaat ləvazimatlarıyla təmin etmək. Ləvazimatlara qoruyucu geyim və təhlükəsizlik avadanlığı da daxil edilir. | C16: cəm | F16: 65000
A17: 1.6 | B17: Müvəqqəti İşlər | F17: =D17*E17 -> 0
A18: 1.6.1 | B18: Müvəqqəti meydança (ərazi), yol və binalar | C18: cəm | F18: 35000
A19: 1.6.5 | B19: İcraçının özünün məişət obyektləri ilə (icraçının ofisi, istehsalat bazası, düşərgə, ayaqyolu, laboratoriya, anbar və digər tikililərin) təmin etməsi | C19: cəm | F19: 25000
A20: CƏM: | F20: =SUM(F5:F19) -> 965400

Sheet Scope_Matrix
B2: RESPONSIBILITY MATRIX FOR ARCHITECTURE WORKS/MEMARLIQ İŞLƏRİ ÜÇÜN TƏRƏFLƏRİN MƏSULİYYƏT CƏDVƏLİ
B4: ITEM NO | C4: İŞLƏRİN TƏSVİRİ | D4: DESCRIPTION | E4: Supplied By/ Təchiz edən | G4: Paid By/ Ödəyən | I4: REMARKS/QEYDLƏR
E5: CON | F5: SUBCON | G5: CON | H5: SUBCON
B6: 1 | C6: ƏSAS İŞÇİ HEYƏTİ | D6: DIRECT WORKMANSHIP
B7: 1.1 | C7: Əmək haqqı xərcləri | D7: Wage Expenses | F7: X | H7: X
B8: 1.2 | C8: Beynəlxalq nəqliyyat xərcləri | D8: International Transportation Expenses | F8: X | H8: X
B9: 1.3 | C9: Azərbaycan daxili nəqliyyat xərcləri | D9: Transportation Expenses Inside Azerbaijan | F9: X | H9: X
B10: 1.4 | C10: Qidalanma xərcləri (3 yemək) | D10: Food Expenses (3 meal) | F10: X | H10: X
B11: 1.5 | C11: İşçilərin Yerləşim Xərcləri | D11: Accommodation Expenses | F11: X | H11: X
B12: 1.6 | C12: İş Forması/Geyim | D12: Working Uniform/Dress | F12: X | H12: X
B13: 1.7 | C13: İşçilərin Nəqliyyatı | D13: Local Transportation | F13: X | H13: X
B14: 1.8 | C14: Sosial Təminat & Tibbi Xərclər | D14: Social Security & Medical Expenses | F14: X | H14: X
B15: 1.9 | C15: Viza Qeydiyyatı Xərcləri | D15: Visa Registration Expenses | F15: X | H15: X
B16: 1.10 | C16: Karantina Xərcləri (Əmək haqqı və. s) | D16: Quarantine Expenses (Wage and Other) | F16: X | H16: X
B17: 2 | C17: DİGƏR İŞÇİ HEYƏTLƏRİ | D17: INDIRECT PERSONNEL
B18: 2.1 | C18: Əmək haqqı xərcləri | D18: Wage Expenses | F18: X | H18: X
B19: 2.2 | C19: Beynəlxalq nəqliyyat xərcləri | D19: International Transportation Expenses | F19: X | H19: X
B20: 2.3 | C20: Azərbaycan daxili nəqliyyat xərcləri | D20: Transportation Expenses Inside Azerbaijan | F20: X | H20: X
B21: 2.4 | C21: Qidalanma xərcləri | D21: Food Expenses (3 meal) | F21: X | H21: X
B22: 2.5 | C22: İşçilərin Yerləşim Xərcləri | D22: Accommodation Expenses | F22: X | H22: X
B23: 2.6 | C23: İş Forması/Geyimi | D23: Working Uniform/Dress | F23: X | H23: X
B24: 2.7 | C24: İşçilərin Nəqliyyatı | D24: Local Transportation | F24: X | H24: X
B25: 2.8 | C25: Sosial Təminat & Tibbi Xərclər | D25: Social Security & Medical Expenses | F25: X | H25: X
B26: 2.9 | C26: Viza Qeydiyyatı Xərcləri | D26: Visa Registration Expenses | F26: X | H26: X
B27: 2.10 | C27: Karantina Xərcləri (Əmək haqqı və. s) | D27: Quarantine Expenses (Wage and Other) | F27: X | H27: X
B28: 3 | C28: TİKİNTİ SAHƏSİNİN XƏRCLƏRİ | D28: SITE OVERHEADS
B29: 3.1 | C29: Mobilizasiya xərcləri | D29: Mobilization Cost | F29: X | H29: X
B30: 3.2 | C30: Sahə ofisləri | D30: Site Offices | F30: X | H30: X
B31: 3.3 | C31: Alətlər və tikinti materialları üçün anbar | D31: Warehouse for Handtools and Consumables | F31: X | H31: X
B32: 3.4 | C32: Müvəqqəti su və Kanalizasiya | D32: Temporary water and waste water | F32: X | H32: X
B33: 3.5 | C33: Elektrik mənbəyinin təmin edilməsi | D33: Prodiving electrical power point | E33: X | G33: X
B34: 3.6 | C34: Elektrik xərcləri | D34: Electricity Costs | E34: X | G34: X
B35: 3.7 | C35: İşıqlandırma xərcləri | D35: Lighting Costs | F35: X | H35: X
B36: 3.8 | C36: Elektrik kabelləri | D36: Electrical cables from power point | F36: X | H36: X
B37: 3.9 | C37: Zibillərin yığılması və Tikinti sahəsinin təmizliyi | D37: Garbage removal & Site Cleaning | F37: X | H37: X
B38: 3.10 | C38: Qar təmizliyi | D38: Snow Removing | F38: X | H38: X
B39: 3.11 | C39: Ofis komputerləri, avadanlıqlar və mebellər | D39: Office Computers, Devices and Furniture | F39: X | H39: X
B40: 3.12 | C40: Ofis internet xərcləri | D40: Office internet expenses | F40: X | H40: X
B41: 3.13 | C41: Mobil telefon | D41: Mobile phones | F41: X | H41: X
B42: 3.14 | C42: Stasionar | D42: Stationary | F42: X | H42: X
...

Sheet Org_chart
G5: PROJECT ORGANIZATIONAL CHART / LAYİHƏNİN İDARƏETMƏ STRUKTURU
Y7: Layihə üzrə idarəetmə və mühəndis-texniki heyət
Y9: № | Z9: Vəzifə | AA9: Say
A10: LAYİHƏ RƏHBƏRİ / LAYİHƏ MENECERİ | Y10: 1 | Z10: Layihə Meneceri | AA10: 1
A11: │ | Y11: 2 | Z11: Layihə Menecerinin köməkçisi | AA11: 2
A12: ┌────────────────────────┼────────────────────────┐ | Y12: 3 | Z12: Planlama üzrə Menecer | AA12: 1
A13: │ │ │ | Y13: 4 | Z13: Layihələndirmə üzrə Menecer | AA13: 1
A14: ▼ ▼ ▼ | Y14: 5 | Z14: Shopdrawing / As-built üzrə texniki heyət | AA14: 4
A15: MENECER KÖMƏKÇİLƏRİ PLANLAMA MENECERİ LAYİHƏLƏNDİRMƏ | Y15: 6 | Z15: Sahə xarici texniki layihələndirmə heyəti | AA15: 2
A16: 2 nəfər 1 nəfər MENECERİ | Y16: 7 | Z16: Dəmir-beton işləri üzrə Tikinti Meneceri | AA16: 1
A17: │ | Y17: 8 | Z17: Ümumi tikinti işləri üzrə Tikinti Meneceri | AA17: 1
A18: ▼ | Y18: 9 | Z18: Nəzarətçi | AA18: 2
A19: SHOPDRAWING / AS-BUILT | Y19: 10 | Z19: Sınaq və istismara vermə mühəndisi | AA19: 1
A20: TEXNİKİ KOMANDA | Y20: 11 | Z20: Sınaq və istismara vermə mühəndisinin köməkçisi | AA20: 1
A21: 4 nəfər | Y21: 12 | Z21: QA/QC Meneceri | AA21: 1
... A28: │ ┌──────┼──────┐ │ | Y28: 19 | Z28: Digər texniki və inzibati heyət | AA28: 1
A29: │ │ │ │ ▼
A30: │ ▼ ▼ ▼ SƏTƏM KÖMƏKÇİSİ | Y30: Qeyd: Layihənin iş həcminə və iş qrafikinə uyğun olaraq fəhlə heyətinin sayı və tərkibi işlərin intensivliyinə əsasən dəyişdirilə bilər.
A31: │ QA/QC QA/QC SINAQ 1 nəfər
A32: │ ELEKTRİK MEXANİK VƏ
A33: │ MÜH. MÜH. İSTİSMAR
A34: │ MÜH.
A35: │
A36: ├───────────────┬───────────────┐
A37: ▼ ▼ ▼
A38: ARMATUR İŞLƏRİ QƏLİB İŞLƏRİ BETON İŞLƏRİ
A39: │ │ │
A40: └───────────────┼───────────────┘
A41: ▼
A42: SAHƏ İCRA HEYƏTİ
... A51: İŞÇİLƏRİ
B57: 2. BAŞ OFİSİN LAYİHƏ ÜZRƏ İDARƏETMƏ VƏ FUNKSİONAL DƏSTƏK STRUKTURU
C62: ISCG MMC – BAŞ OFİS | Z62: Baş Ofisin layihə üzrə funksiyaları
C63: │
C64: ▼ | Z64: Baş Ofis funksiyası | AA64: Layihəyə göstərilən dəstək
C65: BAŞ DİREKTOR | Z65: Baş Direktor | AA65: Layihənin ümumi strateji və inzibati idarə edilməsi, əsas qərarların qəbul edilməsi
C66: │ | Z66: Texniki Direktorluq / Baş Mühəndis | AA66: Texniki məsələlərə, metodologiyaya və layihə həllərinə dəstək
C67: ┌───────────────┬────────┼────────┬───────────────┐ | Z67: Kommersiya / Tender Şöbəsi | AA67: Müqavilə, kommersiya məsələləri, dəyişikliklər və yazışmalar
C68: │ │ │ │ │ | Z68: Maliyyə və Mühasibatlıq | AA68: Büdcə, ödənişlər, əməkhaqqı, maliyyə hesabatları və vergi məsələləri
C69: ▼ ▼ ▼ ▼ ▼ | Z69: Satınalma və Təchizat | AA69: Beton, armatur, qəlib materialları, XPS, hidroizolyasiya və digər materialların satın alınması
...

Sheet Planning
B2: Work Schedule / İş cədvəli
B3: Description of Work / İşin təsviri | C3: Start / Başlanğıc | D3: Finish / Bitmə tarixi | E3: Duration / Müddət
B4: Metal ve Demir beton konstruksiya işləri | E4: 360
A8: № | B8: İşlərin adı | C8: Başlanğıc | D8: Bitmə | E8: Müddət
A9: 1 | B9: Mobilizasiya və sahənin təşkili | C9: 1-ci gün | D9: 10-cu gün | E9: 10 gün
A10: 2 | B10: Topoqrafik ölçmə və nişanlama işləri | C10: 1-ci gün | D10: 10-cu gün | E10: 10 gün
A11: 3 | B11: Qazıntı işləri | C11: 5-ci gün | D11: 45-ci gün | E11: 41 gün
A12: 4 | B12: Qazılmış torpağın daşınması/utilizasiyası | C12: 10-cu gün | D12: 45-ci gün | E12: 36 gün
A13: 5 | B13: Mexaniki sıxlaşdırma | C13: 25-ci gün | D13: 50-ci gün | E13: 26 gün
A14: 6 | B14: Çınqıl/qırmadaşla dolğu və sıxlaşdırma | C14: 45-ci gün | D14: 60-cı gün | E14: 16 gün
A15: 7 | B15: Geri doldurma işləri | C15: 50-ci gün | D15: 70-ci gün | E15: 21 gün
A16: 8 | B16: Polietilen plyonkanın sərilməsi | C16: 55-ci gün | D16: 65-ci gün | E16: 11 gün
A17: 9 | B17: B7.5 hazırlıq betonunun tökülməsi | C17: 60-cı gün | D17: 75-ci gün | E17: 16 gün
A18: 10 | B18: Hidroizolyasiya işləri | C18: 70-ci gün | D18: 100-cü gün | E18: 31 gün
A19: 11 | B19: XPS və drenaj lövhələrinin quraşdırılması | C19: 90-cı gün | D19: 115-ci gün | E19: 26 gün
A20: 12 | B20: Tava bünövrə – armatur işləri | C20: 70-ci gün | D20: 110-cu gün | E20: 41 gün
... A36: 28 | B36: Yekun təhvil və demobilizasiya | C36: 295-ci gün | D36: 300-cü gün | E36: 6 gün
B38: Ehtiyat/rezerv müddəti | C38: 60 gün
